Workbook

Sheet legacy
A1: asset class | B1: region | C1: subregion | D1: description | E1: factor_name | G1: Active Vol
A2: Equities | B2: USD | C2: Equities | D2: S&P 500 | E2: SPX | F2: SPX
A3: Equities | B3: USD | C3: Equities | D3: Russell 2000 | E3: RTY | F3: RTY
A4: Equities | B4: USD | C4: Equities | D4: Dow Jones 30 | E4: DOW | F4: INDU
A5: Equities | B5: USD | C5: Equities | D5: Nasdaq 100 | E5: NDX | F5: NDX
A6: Equities | B6: USD | C6: Equities | D6: Technology | E6: XLK | F6: XLK
A7: Equities | B7: USD | C7: Sectors | D7: Industrials | E7: XLI | F7: XLI
A8: Equities | B8: USD | C8: Sectors | D8: Financials | E8: XLF | F8: XLF
A9: Equities | B9: USD | C9: Sectors | D9: Regional Banks | E9: KRE | F9: KRE | G9: 0
A10: Equities | B10: USD | C10: Sectors | D10: Communications | E10: XLC | F10: XLC
A11: Equities | B11: USD | C11: Sectors | D11: Energy | E11: XLE | F11: XLE
A12: Equities | B12: USD | C12: Sectors | D12: Discretionary | E12: XLY | F12: XLY
A13: Equities | B13: USD | C13: Sectors | D13: Materials | E13: XLB | F13: XLB
A14: Equities | B14: USD | C14: Sectors | D14: Health Care | E14: XLV | F14: XLV
A15: Equities | B15: USD | C15: Sectors | D15: Utilities | E15: XLU | F15: XLU
A16: Equities | B16: USD | D16: Staples | E16: XLP | F16: XLP
A17: Equities | B17: USD | D17: Real Estate | E17: REIT | F17: IYR
A18: Equities | B18: USD | D18: TSX 60 (Canada) | E18: TSX | F18: SPTSX60
A19: Equities | B19: EUR | D19: Eurostoxx 50 | E19: SX5E | F19: SX5E
A20: Equities | B20: EUR | D20: Eurostoxx Banks | E20: SX7E | F20: SX7E
A21: Equities | B21: EUR | D21: DAX (Germany) | E21: DAX | F21: DAX
A22: Equities | B22: EUR | D22: CAC 40 (France) | E22: CAC | F22: CAC
A23: Equities | B23: EUR | D23: FTSE 100 (UK) | E23: FTSE | F23: UKX
A24: Equities | B24: JPY | D24: Nikkei 225 (Japan) | E24: NKY | F24: NKY
A25: Equities | B25: JPY | D25: Topix (Japan domenstic) | E25: TPX | F25: TPX
A26: Equities | B26: EM | D26: Hang Seng (Hong Kong) | E26: HSI | F26: HSI
A27: Equities | B27: EM | D27: KOSPI 200 (Korea) | E27: KOSPI | F27: KOSPI2
A28: Equities | B28: EM | D28: NIFTY 50 (India) | E28: NIFTY | F28: NIFTY5
A29: Equities | B29: EM | D29: MSCI Brazil Index | E29: EWZ | F29: EWZ | G29: 0
A30: Equities | B30: EM | D30: CSI 300 (China) | E30: ASHR | F30: ASHR
A31: Equities | B31: EM | D31: FTSE China 50 | E31: FXI | F31: FXI
A32: Equities | B32: EM | D32: MSCI EM | E32: EEM | F32: EEM
A33: Credit | B33: USD | D33: US IG CDX | E33: IG | F33: IBOXUMAE
A34: Credit | B34: USD | D34: US HY CDX | E34: HY | F34: IBOXHYSE
A35: Credit | B35: USD | D35: US IG Bond ETF | E35: LQD | F35: LQD
A36: Credit | B36: USD | D36: US HY Bond ETF | E36: HYG | F36: HYG
A37: Credit | B37: USD | D37: Leveraged Loans | E37: LOAN | F37: BKLN | G37: 0
A38: Credit | B38: EUR | D38: Eur MAIN CDX (IG) | E38: MAIN | F38: ITRXEBE
A39: Credit | B39: EUR | D39: Eur XOVER CDX (HY) | E39: XOVER | F39: ITRXEXE
A40: Credit | B40: EUR | D40: Eur Sen Fin CDX | E40: SENFIN | F40: ITRXESE
...

Sheet gpt
A1: Asset Class | B1: Region | C1: Ticker | D1: Description | E1: Underlying
A2: Equities | B2: USD | C2: SPY | D2: SPDR S&P 500 ETF Trust | E2: S&P 500 Index
A3: Equities | B3: USD | C3: IWM | D3: iShares Russell 2000 ETF | E3: Russell 2000 Index
A4: Equities | B4: USD | C4: QQQ | D4: Invesco QQQ Trust | E4: Nasdaq-100 Index
A5: Equities | B5: USD | C5: DIA | D5: SPDR Dow Jones Industrial Average ETF Trust | E5: Dow Jones Industrial Average
A6: Equities | B6: USD | C6: MDY | D6: SPDR S&P MidCap 400 ETF Trust | E6: S&P MidCap 400 Index
A7: Equities | B7: USD | C7: VNQ | D7: Vanguard Real Estate ETF | E7: MSCI US REIT Index
A8: Equities | B8: USD | C8: PFF | D8: iShares Preferred and Income Securities ETF | E8: U.S. preferred stocks
A9: Equities | B9: USD | C9: XLK | D9: Technology Select Sector SPDR Fund | E9: U.S. technology sector
A10: Equities | B10: USD | C10: XLI | D10: Industrial Select Sector SPDR Fund | E10: U.S. industrial sector
A11: Equities | B11: USD | C11: XLF | D11: Financial Select Sector SPDR Fund | E11: U.S. financial sector
A12: Equities | B12: USD | C12: KRE | D12: SPDR S&P Regional Banking ETF | E12: U.S. regional banking sector
... A61: Commodities | B61: USD | C61: DBC | D61: Invesco DB Commodity Index Tracking Fund | E61: Broad commodity index

Sheet data_new
A5: {=_xlfn.XMATCH(C5:C65,data[factor_name])} -> 1 | C5: SPY | D5: {=IF(G5:G65<>0,G5:G65,_xlfn.XLOOKUP(C5:C65,data[factor_name],data[description]))} -> S&P 500 | E5: {=IF(ISERROR(_xlfn.ANCHORARRAY(M5)),#N/A,IFERROR(_xlfn.ANCHORARRAY(N5),_xlfn.ANCHORARRAY(O5)))} -> SPDR S&P 500 ETF Trust | F5: {=_xlfn.XLOOKUP(C5:C65,legacy!E2:E81,legacy!D2:D81)} -> #N/A | M5: {=IFERROR(_xlfn.ANCHORARRAY(N5)<>_xlfn.ANCHORARRAY(O5),0)} -> FALSE | N5: {=_xlfn.LET(_xlpm.x,_xlfn.XLOOKUP(C5:C65,data[factor_name],data[Description_GPT]),IF(_xlpm.x=0,#N/A,_xlpm.x))} -> SPDR S&P 500 ETF Trust | O5: {=_xlfn.XLOOKUP(C5:C65,gpt!C2:C61,gpt!D2:D61)} -> SPDR S&P 500 ETF Trust
A6: 3 | C6: MDY | D6: S&P 400 | E6: SPDR S&P MidCap 400 ETF Trust | F6: #N/A | G6: S&P 400 | M6: FALSE | N6: SPDR S&P MidCap 400 ETF Trust | O6: SPDR S&P MidCap 400 ETF Trust
A7: 2 | C7: IWM | D7: Russell 2000 | E7: iShares Russell 2000 ETF | F7: #N/A | M7: FALSE | N7: iShares Russell 2000 ETF | O7: iShares Russell 2000 ETF
A8: 5 | C8: QQQ | D8: Nasdaq 100 | E8: Invesco QQQ Trust | F8: #N/A | M8: FALSE | N8: Invesco QQQ Trust | O8: Invesco QQQ Trust
A9: 6 | C9: DIA | D9: Dow Jones 30 | E9: SPDR Dow Jones Industrial Average ETF Trust | F9: #N/A | M9: FALSE | N9: SPDR Dow Jones Industrial Average ETF Trust | O9: SPDR Dow Jones Industrial Average ETF Trust
A10: 7 | C10: XLK | D10: Technology | E10: Technology Select Sector SPDR Fund | F10: Technology | G10: Technology | M10: FALSE | N10: Technology Select Sector SPDR Fund | O10: Technology Select Sector SPDR Fund
A11: 8 | C11: XLI | D11: Industrials | E11: Industrial Select Sector SPDR Fund | F11: Industrials | G11: Industrials | M11: FALSE | N11: Industrial Select Sector SPDR Fund | O11: Industrial Select Sector SPDR Fund
A12: 9 | C12: XLF | D12: Financials | E12: Financial Select Sector SPDR Fund | F12: Financials | G12: Financials | M12: FALSE | N12: Financial Select Sector SPDR Fund | O12: Financial Select Sector SPDR Fund
A13: 10 | C13: KRE | D13: Regional Banks | E13: SPDR S&P Regional Banking ETF | F13: Regional Banks | G13: Regional Banks | M13: FALSE | N13: SPDR S&P Regional Banking ETF | O13: SPDR S&P Regional Banking ETF
A14: 11 | C14: XLC | D14: Communications | E14: Communication Services Select Sector SPDR | F14: Communications | G14: Communications | M14: FALSE | N14: Communication Services Select Sector SPDR | O14: Communication Services Select Sector SPDR
A15: 12 | C15: XLE | D15: Energy | E15: Energy Select Sector SPDR Fund | F15: Energy | G15: Energy | M15: FALSE | N15: Energy Select Sector SPDR Fund | O15: Energy Select Sector SPDR Fund
A16: 13 | C16: XLY | D16: Discretionary | E16: Consumer Discretionary Select Sector SPDR | F16: Discretionary | G16: Discretionary | M16: FALSE | N16: Consumer Discretionary Select Sector SPDR | O16: Consumer Discretionary Select Sector SPDR
A17: 14 | C17: XLB | D17: Materials | E17: Materials Select Sector SPDR Fund | F17: Materials | G17: Materials | M17: FALSE | N17: Materials Select Sector SPDR Fund | O17: Materials Select Sector SPDR Fund
A18: 15 | C18: XLV | D18: Health Care | E18: Health Care Select Sector SPDR Fund | F18: Health Care | G18: Health Care | M18: FALSE | N18: Health Care Select Sector SPDR Fund | O18: Health Care Select Sector SPDR Fund
A19: 16 | C19: XLU | D19: Utilities | E19: Utilities Select Sector SPDR Fund | F19: Utilities | G19: Utilities | M19: FALSE | N19: Utilities Select Sector SPDR Fund | O19: Utilities Select Sector SPDR Fund
A20: 17 | C20: XLP | D20: Staples | E20: Consumer Staples Select Sector SPDR Fund | F20: Staples | G20: Staples | M20: FALSE | N20: Consumer Staples Select Sector SPDR Fund | O20: Consumer Staples Select Sector SPDR Fund
A21: 18 | C21: IYR | D21: Real Estate | E21: iShares U.S. Real Estate ETF | F21: #N/A | G21: Real Estate | M21: FALSE | N21: iShares U.S. Real Estate ETF | O21: iShares U.S. Real Estate ETF
A22: 19 | C22: VNQ | D22: Real Estate 2 | E22: Vanguard Real Estate ETF | F22: #N/A | G22: Real Estate 2 | M22: FALSE | N22: Vanguard Real Estate ETF | O22: Vanguard Real Estate ETF
A23: 22 | C23: AIQ | D23: AI | E23: Global X Artificial Intelligence & Technology ETF | F23: #N/A | G23: AI | M23: FALSE | N23: Global X Artificial Intelligence & Technology ETF | O23: Global X Artificial Intelligence & Technology ETF
A24: 27 | C24: PFF | D24: Preferred | E24: iShares Preferred and Income Securities ETF | F24: #N/A | G24: Preferred | M24: FALSE | N24: iShares Preferred and Income Securities ETF | O24: iShares Preferred and Income Securities ETF
A25: 31 | C25: FEZ | D25: Eurostoxx 50 | E25: SPDR EURO STOXX 50 ETF | F25: #N/A | M25: FALSE | N25: SPDR EURO STOXX 50 ETF | O25: SPDR EURO STOXX 50 ETF
A26: 32 | C26: SX7E | D26: Eurostoxx Banks | E26: iShares STOXX Europe 600 Banks | F26: Eurostoxx Banks | M26: 0 | N26: #N/A | O26: iShares STOXX Europe 600 Banks
A27: 33 | C27: EWU | D27: FTSE 100 | E27: iShares FTSE United Kingdom ETF | F27: #N/A | M27: FALSE | N27: iShares FTSE United Kingdom ETF | O27: iShares FTSE United Kingdom ETF
A28: 34 | C28: DAX | D28: DAX (Germany) | E28: Xtrackers DAX Equity ETF | F28: DAX (Germany) | M28: FALSE | N28: Xtrackers DAX Equity ETF | O28: Xtrackers DAX Equity ETF
A29: 35 | C29: EWC | D29: MSCI Canada | E29: iShares MSCI Canada ETF | F29: #N/A | M29: 0 | N29: iShares MSCI Canada ETF | O29: #N/A
A30: 36 | C30: FTSEMIB.MI | D30: FTSE MIB (Italy) | E30: iShares MSCI Italy ETF | F30: #N/A | M30: 0 | N30: #N/A | O30: iShares MSCI Italy ETF
A31: 37 | C31: CAC | D31: CAC 40 (France) | E31: Lyxor CAC 40 ETF | F31: CAC 40 (France) | M31: FALSE | N31: Lyxor CAC 40 ETF | O31: Lyxor CAC 40 ETF
A32: 38 | C32: EWI | D32: MSCI Italy | E32: iShares MSCI Italy ETF | F32: #N/A | M32: FALSE | N32: iShares MSCI Italy ETF | O32: iShares MSCI Italy ETF
A33: 39 | C33: ^IBEX | D33: IBEX 35 (Spain) | E33: IBEX 35 ETF | F33: #N/A | M33: 0 | N33: #N/A | O33: IBEX 35 ETF
A34: 40 | C34: EWP | D34: MSCI Spain | E34: iShares MSCI Spain ETF | F34: #N/A | M34: FALSE | N34: iShares MSCI Spain ETF | O34: iShares MSCI Spain ETF
A35: 41 | C35: ^N225 | D35: Nikkei 225 | E35: Nikkei 225 ETF | F35: #N/A | M35: FALSE | N35: Nikkei 225 ETF | O35: Nikkei 225 ETF
A36: 42 | C36: TPX | D36: TOPIX | E36: iShares TOPIX ETF | F36: Topix (Japan domenstic) | M36: FALSE | N36: iShares TOPIX ETF | O36: iShares TOPIX ETF
A37: 43 | C37: FXI | D37: China Large-Cap | E37: iShares China Large-Cap ETF | F37: FTSE China 50 | M37: FALSE | N37: iShares China Large-Cap ETF | O37: iShares China Large-Cap ETF
A38: 44 | C38: ASHR | D38: CSI 300 (China) | E38: Xtrackers Harvest CSI 300 China A-Shares ETF | F38: CSI 300 (China) | M38: FALSE | N38: Xtrackers Harvest CSI 300 China A-Shares ETF | O38: Xtrackers Harvest CSI 300 China A-Shares ETF
A39: 45 | C39: KWEB | D39: CSI China Internet | E39: KraneShares CSI China Internet ETF | F39: #N/A | M39: FALSE | N39: KraneShares CSI China Internet ETF | O39: KraneShares CSI China Internet ETF
A40: 47 | C40: LQD | D40: iShares iBoxx $ Investment Grade Corporate Bond ETF | E40: iShares iBoxx $ Investment Grade Corporate Bond ETF | F40: US IG Bond ETF | M40: FALSE | N40: iShares iBoxx $ Investment Grade Corporate Bond ETF | O40: iShares iBoxx $ Investment Grade Corporate Bond ETF
A41: 49 | C41: HYG | D41: iShares iBoxx $ High Yield Corporate Bond ETF | E41: iShares iBoxx $ High Yield Corporate Bond ETF | F41: US HY Bond ETF | M41: FALSE | N41: iShares iBoxx $ High Yield Corporate Bond ETF | O41: iShares iBoxx $ High Yield Corporate Bond ETF
A42: 50 | C42: LQDH | D42: Hedged LQD | E42: iShares Interest Rate Hedged Corporate Bond ETF | F42: #N/A | M42: 0 | N42: #N/A | O42: iShares Interest Rate Hedged Corporate Bond ETF
A43: 51 | C43: HYGH | D43: Hedged HYG | E43: iShares Interest Rate Hedged High Yield Bond ETF | F43: #N/A | M43: 0 | N43: #N/A | O43: iShares Interest Rate Hedged High Yield Bond ETF
A44: 55 | C44: SHY | D44: 1-3 Year Treasury | E44: iShares 1-3 Year Treasury Bond ETF | F44: 1-3 Year Treasury ETF | M44: FALSE | N44: iShares 1-3 Year Treasury Bond ETF | O44: iShares 1-3 Year Treasury Bond ETF
...

Sheet lior
A1: tip | B1: {=_xlfn.XMATCH(A1:A9,data[factor_name])} -> 59 | D1: {=_xlfn.XLOOKUP(_xlfn._TRO_ALL(A:A),data[factor_name],data[Active])} -> 1
A2: vtip | B2: 60 | D2: 1
A3: cmbs | B3: 65 | D3: 1
A4: vmbs | B4: 64 | D4: 1
A5: gld | B5: 70 | D5: 1
A6: lqd | B6: 47 | D6: 1
A7: lqdh | B7: 50 | D7: 1
A8: hyg | B8: 49 | D8: 1
A9: hygh | B9: 51 | D9: 1
D10: #N/A
D11: #N/A
A12: {=_xlfn.TEXTSPLIT(data!#REF!,," ")} -> #REF! | B12: {=_xlfn.XMATCH(_xlfn.ANCHORARRAY(A12),data[factor_name])} -> #REF! | D12: #REF!
D13: #N/A
D14: #N/A
D15: #N/A
D16: #N/A
D17: #N/A
D18: #N/A
D19: #N/A
D20: #N/A
A21: XLK | D21: 1
A22: XLI | D22: 1
A23: XLF | D23: 1
A24: KRE | D24: 1
A25: XLC | D25: 1
A26: XLE | D26: 1
A27: XLY | D27: 1
A28: XLB | D28: 1
A29: XLV | D29: 1
A30: XLU | D30: 1
A31: XLP | D31: 1
A32: IYR | D32: 1

Sheet read_composites
A1: {=composities[#Headers]} -> portfolio_name | B1: factor_name | C1: weight
A2: {=composities[]} -> FED | B2: SHY | C2: 1
A3: FED | B3: BSV | C3: 1
A4: AI | B4: AIQ | C4: 1
A5: AI | B5: QQQ | C5: 0.25
A6: AI | B6: IWM | C6: -0.25
A7: GEOPOLITICS | B7: GLD | C7: 0.65
A8: GEOPOLITICS | B8: USO | C8: 0.3
A9: GEOPOLITICS | B9: ^VIX3M | C9: -0.15
A10: GEOPOLITICS | B10: FEZ | C10: -0.05
A11: 2s10s | B11: SHY | C11: -3.863388
A12: 2s10s | B12: IEF | C12: 1
A13: XLPXLY | B13: XLP | C13: 1
A14: XLPXLY | B14: XLY | C14: -1
... A28: PRIVATES | B28: LQDH | C28: -0.5

Sheet risk_parity
A1: SPY | B1: {=_xlfn.XLOOKUP(_xlfn._TRO_ALL(A:A),data[factor_name],data[asset_class],"")} -> Equities | F1: ="['"&_xlfn.TEXTJOIN("', '",,_xlfn._TRO_ALL(A:A))&"']" -> ['SPY', 'FEZ', '^N225', 'LQDH', 'HYGH', 'EMB', 'IEI', 'IEF', 'TLT', 'FXE', 'FXY', 'FXF', 'TIP', 'VMBS', 'CMBS', 'GLD', 'USO']
A2: FEZ | B2: Equities
A3: ^N225 | B3: Equities
A5: LQDH | B5: Credit
A6: HYGH | B6: Credit
A7: EMB | B7: Rates
A9: IEI | B9: Rates
A10: IEF | B10: Rates
A11: TLT | B11: Rates
A13: FXE | B13: Currencies
A14: FXY | B14: Currencies
A15: FXF | B15: Currencies
A17: TIP | B17: Rates
... A22: USO | B22: Commodities

Sheet tradewar
B1: {=TRANSPOSE(_xlfn.DROP(_xlfn._xlws.FILTER(composities[],composities[portfolio_name]="TRADEWAR"),,1))} -> GLD | C1: FXY | D1: FXF | E1: ^VIX3M | F1: XLP | G1: XLY
A2: =TODAY()-1 -> 46186 | B2: 0.20547945 | C2: 0.2970297 | D2: 0.36585366 | E2: -0.0375 | F2: 0.15 | G2: -0.15

Sheet tracking
A1: date | B1: SPY | C1: FEZ | D1: ^N225 | E1: LQDH | F1: HYGH | G1: EMB | H1: IEI | I1: IEF | J1: TLT | K1: FXE | L1: FXY | M1: FXF | N1: TIP | O1: VMBS | P1: CMBS | Q1: GLD | R1: USO
A2: {=DATE(_xlfn.SEQUENCE(12,,2025,-1),1,1)} -> 45658 | B2: 1
A3: 45292 | E3: 1
A4: 44927 | J4: 1
A5: 44562 | K5: 1
A6: 44197 | O6: 1
A7: 43831 | R7: 1
A8: 43466 | B8: 1
A9: 43101 | E9: 1
A10: 42736 | J10: 1
A11: 42370 | K11: 1
A12: 42005 | O12: 1
A13: 41640 | R13: 1

Sheet yf_desc
A1: ticker | B1: shortName | C1: longName | D1: longBusinessSummary | E1: Column1
A2: SPY | B2: SPDR S&P 500 | C2: SPDR S&P 500 ETF | D2: The trust seeks to achieve its investment objective by holding a portfolio of the common stocks that are included in the index, with the weight of each stock in the portfolio substantially corresponding to the weight of such stock in the index.
A3: IWM | B3: iShares Russell 2000 ETF | C3: iShares Russell 2000 ETF | D3: The fund generally invests at least 80% of its assets in the component securities of its underlying index and in investments that have economic characteristics that are substantially identical to the component securities of its underlying index (i.e., depositary receipts representing securities of the underlying index) and may invest up to 20% of its assets in certain futures, options and swap contracts, cash and cash equivalents.
A4: MDY | B4: SPDR S&P MidCap 400 ETF Trust | C4: SPDR S&P MIDCAP 400 ETF Trust | D4: The Trust seeks to achieve its investment objective by holding a portfolio of the common stocks that are included in the index (the “Portfolio”), with the weight of each stock in the Portfolio substantially corresponding to the weight of such stock in the index.
A5: RSP | B5: Invesco S&P 500 Equal Weight ET | C5: Invesco S&P 500 Equal Weight ETF | D5: The fund generally will invest at least 90% of its total assets in securities that comprise the underlying index. Strictly in accordance with its guidelines and mandated procedures, the index provider compiles, maintains and calculates the underlying index, which consists of all of the of the S&P 500® Index.
A6: QQQ | B6: Invesco QQQ Trust, Series 1 | C6: Invesco QQQ Trust | D6: To maintain the correspondence between the composition and weights of the securities in the trust (the "securities") and the stocks in the NASDAQ-100 Index®, the adviser adjusts the securities from time to time to conform to periodic changes in the identity and/or relative weights of index securities. The composition and weighting of the securities portion of a portfolio deposit are also adjusted to conform to changes in the index.
A7: DIA | B7: SPDR Dow Jones Industrial Avera | C7: SPDR Dow Jones Industrial Average ETF Trust | D7: The Trust’s Portfolio consists of substantially all of the component common stocks that comprise the DJIA, which are weighted in accordance with the terms of the Trust Agreement.
A8: XLK | B8: SPDR Select Sector Fund - Techn | C8: The Technology Select Sector SPDR Fund | D8: In seeking to track the performance of the index, the fund employs a replication strategy, which means that the fund typically invests in substantially all of the securities represented in the index in approximately the same proportions as the index. It generally invests substantially all, but at least 95%, of its total assets in the securities comprising the index. The fund is non-diversified.
A9: XLI | B9: SPDR Select Sector Fund - Indus | C9: The Industrial Select Sector SPDR Fund | D9: Under normal market conditions, the fund generally invests substantially all, but at least 95%, of its total assets in the securities comprising the index. The index includes companies that have been identified as Industrial companies by the Global Industry Classification Standard, including securities of companies from the following industries: aerospace and defense; industrial conglomerates; marine transportation. It is non-diversified.
A10: XLF | B10: SPDR Select Sector Fund - Finan | C10: The Financial Select Sector SPDR Fund | D10: The fund generally invests substantially all, but at least 95%, of its total assets in the securities comprising the index. The index includes companies that have been identified as Financial companies by the Global Industry Classification Standard, including securities of companies from the following industries: financial services; insurance; banks; capital markets; mortgage real estate investment trusts; and consumer finance. The fund is non-diversified.
A11: KRE | B11: SPDR S&P Regional Banking ETF | C11: SPDR S&P Regional Banking ETF | D11: In seeking to track the performance of the S&P Regional Banks Select Industry Index (the "index"), the fund employs a sampling strategy. It generally invests substantially all, but at least 80%, of its total assets in the securities comprising the index. The index represents the regional banks segment of the S&P Total Market Index ("S&P TMI").
A12: XLC | B12: The Communication Services Sele | C12: The Communication Services Select Sector SPDR ETF Fund | D12: Normally, the fund generally invests substantially all, but at least 95%, of its total assets in the securities comprising the index. The index includes companies that have been identified as Communication Services companies by the GICS®, including securities of companies from the following industries: diversified telecommunication services; wireless telecommunication services; media; entertainment; and interactive media & services. The fund is non-diversified.
A13: XLE | B13: SPDR Select Sector Fund - Energ | C13: The Energy Select Sector SPDR Fund | D13: In seeking to track the performance of the index, the fund employs a replication strategy. It generally invests substantially all, but at least 95%, of its total assets in the securities comprising the index. The index includes companies that have been identified as Energy companies by the GICS®, including securities of companies from the following industries: oil, gas and consumable fuels; and energy equipment and services. It is non-diversified.
... A27: EWC | B27: iShares MSCI Canada Index Fund | C27: iShares MSCI Canada ETF | D27: The fund generally will invest at least 80% of its assets in the component securities of its underlying index and in investments that have economic characteristics that are substantially identical to the component securities of its underlying index. The underlying index is designed to measure broad-based equity performance in Canada. The underlying index includes large- and mid-capitalization companies and may change over time.
A28: FTSEMIB.MI | B28: FTSE MIB Index | C28: FTSE MIB Index
A29: CAC | B29: Camden National Corporation | C29: Camden National Corporation | D29: Camden National Corporation operates as the bank holding company for Camden National Bank that provides various commercial and consumer banking products and services for consumer, institutional, municipal, non-profit, and commercial customers in the United States. The company accepts checking, savings, time, and brokered deposits, as well as deposits with the certificate of deposit account registry system. Its loan products include non-owner-occupied commercial real estate loans; owner-occupied commercial real estate loans; commercial loans; residential real estate loans, including one- to four-family residences; and consumer and home equity loans. In addition, the company provides brokerage and insurance services through its financial offerings consisting of college, retirement, estate planning, mutual funds, strategic asset management accounts, and variable and fixed annuities. Further, it offers a range of fiduciary and asset management, wealth management, investment management and advisory, financial planning, and trustee services. Camden National Corporation was founded in 1875 and is headquartered in Camden, Maine.
A30: EWI | B30: iShares Inc iShares MSCI Italy | C30: iShares MSCI Italy ETF | D30: The fund generally will invest at least 80% of its assets in the component securities of its underlying index and in investments that have economic characteristics that are substantially identical to the component securities of its underlying index. The underlying index is a free float-adjusted market capitalization-weighted index that is designed to measure the performance of the large- and mid-capitalization segments of the equity market in Italy. The fund is non-diversified.
A31: ^IBEX | B31: IBEX 35... | C31: IBEX 35...
A32: EWP | B32: iShares Inc iShares MSCI Spain | C32: iShares MSCI Spain ETF | D32: The fund generally will invest at least 80% of its assets in the component securities of its underlying index and in investments that have economic characteristics that are substantially identical to the component securities of its underlying index. The index is a free float-adjusted market capitalization-weighted index that is designed to measure the performance of the large- and mid-capitalization segments of the equity market in Spain. The fund is non-diversified.
A33: ^N225 | B33: Nikkei 225 | C33: Nikkei 225
A34: FXI | B34: iShares China Large-Cap ETF | C34: iShares China Large-Cap ETF | D34: The fund generally will invest at least 80% of its assets in the component securities of its underlying index and in investments that have economic characteristics that are substantially identical to the component securities of its underlying index. The index designed to measure the performance of the largest companies in the Chinese equity market that trade on the Stock Exchange of Hong Kong and are available to international investors. The fund is non-diversified.
A35: ASHR | B35: Xtrackers Harvest CSI 300 China | C35: Xtrackers Harvest CSI 300 China A-Shares ETF | D35: The fund will normally invest at least 80% of its total assets in securities of issuers that comprise the underlying index. The underlying index is designed to reflect the price fluctuation and performance of the China A-Share market and is composed of the 300 largest and most liquid stocks in the China A-Share market. The underlying index includes small-cap, mid-cap, and large-cap stocks. It is non-diversified.
A36: KWEB | B36: KraneShares Trust KraneShares C | C36: KraneShares CSI China Internet ETF | D36: The fund will invest at least 80% of its net assets in instruments in its underlying index or in instruments that have economic characteristics similar to those in the underlying index. The index is designed to measure the equity market performance of investable publicly traded "China-based companies" whose primary business or businesses are in the Internet and Internet-related sectors, and are listed outside of Mainland China, as determined by the index provider. The fund is non-diversified.
A37: EEM | B37: iShares MSCI Emerging Index Fun | C37: iShares MSCI Emerging Markets ETF | D37: The fund generally will invest at least 80% of its assets in the component securities of its underlying index and in investments that have economic characteristics that are substantially identical to the component securities of its underlying index. The index is designed to measure equity market performance in the global emerging markets. The underlying index includes large- and mid-capitalization companies and may change over time.
A38: LQD | B38: iShares iBoxx $ Investment Grad | C38: iShares iBoxx $ Investment Grade Corporate Bond ETF | D38: The fund will invest at least 80% of its assets in the component securities of the underlying index, and it will invest at least 90% of its assets in fixed income securities of the types included in the underlying index that the advisor believes will help the fund track the underlying index. The underlying index is designed to provide a broad representation of the U.S. dollar-denominated liquid investment-grade corporate bond market.
A39: BSV | B39: Vanguard Short-Term Bond ETF | C39: Vanguard Short-Term Bond Index Fund ETF Shares | D39: This index includes all medium and larger issues of U.S. government, investment-grade corporate, and investment-grade international dollar-denominated bonds that have maturities between 1 and 5 years and are publicly issued. All of the fund's investments will be selected through the sampling process, and at least 80% of its assets will be invested in bonds held in the index.
A40: HYG | B40: iShares iBoxx $ High Yield Corp | C40: iShares iBoxx $ High Yield Corporate Bond ETF | D40: The underlying index is a rules-based index consisting of U.S. dollar-denominated, high yield corporate bonds for sale in the U.S. The fund will invest at least 80% of its assets in the component securities of the underlying index, and the fund will invest at least 90% of its assets in fixed income securities of the types included in the underlying index that the advisor believes will help the fund track the underlying index.
A41: LQDH | B41: iShares Interest Rate Hedged Co | C41: iShares Interest Rate Hedged Corporate Bond ETF | D41: The index is designed to minimize the interest-rate risk exposure of a portfolio composed of U.S. dollar-denominated, investment grade bonds, represented in the index by the underlying fund, by including a series of up to 10 interest rate swap contracts with different maturities. The fund invests, under normal circumstances, at least 80% of its net assets, plus the amount of any borrowings for investment purposes, in component securities and instruments in the index and/or bonds included in the underlying index of the underlying fund.
A42: HYGH | B42: iShares Interest Rate Hedged Hi | C42: iShares Interest Rate Hedged High Yield Bond ETF | D42: The fund seeks to track the investment results of the underlying index, which is designed to minimize the interest-rate risk of a portfolio composed of U.S. dollar-denominated, high yield corporate bonds, represented in the underlying index by the underlying fund. It invests at least 80% of its net assets in component securities and instruments in the fund’s underlying index.
A43: AGG | B43: iShares Core U.S. Aggregate Bon | C43: iShares Core U.S. Aggregate Bond ETF | D43: The index measures the performance of the total U.S. investment-grade bond market. The fund will invest at least 80% of its assets in the component securities of the underlying index and TBAs that have economic characteristics that are substantially identical to the economic characteristics of the component securities of the underlying index, and the fund will invest at least 90% of its assets in fixed income securities of the types included in the underlying index that the advisor believes will help the fund track the underlying index.
A44: ^TNX | B44: CBOE Interest Rate 10 Year T No | C44: CBOE Interest Rate 10 Year T No
A45: SHY | B45: iShares 1-3 Year Treasury Bond | C45: iShares 1-3 Year Treasury Bond ETF | D45: The fund will invest at least 80% of its assets in the component securities of the underlying index and it will invest at least 90% of its assets in U.S. Treasury securities that BFA believes will help the fund track the underlying index. The underlying index measures the performance of public obligations of the U.S. Treasury that have a remaining maturity of greater than or equal to one year and less than three years.
A46: IEI | B46: iShares 3-7 Year Treasury Bond | C46: iShares 3-7 Year Treasury Bond ETF | D46: The index measures the performance of public obligations of the U.S. Treasury that have a remaining maturity of greater than or equal to three years and less than seven years. The fund will invest at least 80% of its assets in the component securities of the index, and the fund will invest at least 90% of its assets in U.S. Treasury securities that BFA believes will help the fund track the index.
A47: IEF | B47: iShares 7-10 Year Treasury Bond | C47: iShares 7-10 Year Treasury Bond ETF | D47: The underlying index measures the performance of public obligations of the U.S. Treasury that have a remaining maturity of greater than or equal to seven years and less than ten years. The fund will invest at least 80% of its assets in the component securities of the underlying index, and the fund will invest at least 90% of its assets in U.S. Treasury securities that the advisor believes will help the fund track the underlying index.
A48: TLT | B48: iShares 20+ Year Treasury Bond | C48: iShares 20+ Year Treasury Bond ETF | D48: The fund will invest at least 80% of its assets in the component securities of the underlying index, and it will invest at least 90% of its assets in U.S. Treasury securities that the advisor believes will help the fund track the underlying index. The underlying index measures the performance of public obligations of the U.S. Treasury that have a remaining maturity greater than or equal to twenty years.
A49: TIP | B49: iShares TIPS Bond ETF | C49: iShares TIPS Bond ETF | D49: The index tracks the performance of inflation-protected public obligations of the U.S. Treasury, commonly known as “TIPS,” that have a remaining maturity of more than one year. The fund will invest at least 80% of its assets in the component securities of the index, and it will invest at least 90% of its assets in U.S. Treasury securities that BFA believes will help the fund track the index.
A50: VTIP | B50: Vanguard Short-Term Inflation-P | C50: Vanguard Short-Term Inflation-Protected Securities Index Fund ETF Shares | D50: The index is a market-capitalization-weighted index that includes all inflation-protected public obligations issued by the U.S. Treasury with remaining maturities of less than 5 years.
A51: MBB | B51: iShares MBS ETF | C51: iShares MBS ETF | D51: The fund will invest at least 80% of its assets in the component securities of the underlying index and TBAs that have economic characteristics that are substantially identical to the economic characteristics of the component securities of the index, and the fund will invest at least 90% of its assets in fixed income securities of the types included in the underlying index that BFA believes will help the fund track the index.
A52: AGNC | B52: AGNC Investment Corp. | C52: AGNC Investment Corp. | D52: AGNC Investment Corp. provides private capital to housing market in the United States. The company invests in residential mortgage pass-through securities and collateralized mortgage obligations for which the principal and interest payments are guaranteed by the United States government-sponsored enterprise or by the United States government agency. It qualifies as a real estate investment trust for federal income tax purposes. The company generally would not be subject to federal or state corporate income taxes if it distributes at least 90% of its taxable income to its stockholders. The company was formerly known as American Capital Agency Corp. and changed its name to AGNC Investment Corp. in September 2016. AGNC Investment Corp. was incorporated in 2008 and is headquartered in Bethesda, Maryland.
A53: VMBS | B53: Vanguard Mortgage-Backed Securi | C53: Vanguard Mortgage-Backed Securities Index Fund ETF Shares | D53: The fund employs an indexing investment approach designed to track the performance of the Bloomberg U.S. MBS Float Adjusted Index. This index covers U.S. agency mortgage-backed pass-through securities issued by the GNMA, the FNMA, and the FHLMC. To be included in the index, pool aggregates must have at least $1 billion currently outstanding and a weighted average maturity of at least 1 year. All of the fund's investments will be selected through the sampling process, and at least 80% of the fund's assets will be invested in bonds included in the index.
...

Sheet election_fact
A6: asset_class | B6: region | C6: factor_name | D6: source | E6: diffusion_type | F6: multiplier | G6: factor_name_new | H6: description_override | I6: Description_GPT | J6: Underlying | K6: Active | L6: hyper_factor | M6: composite | N6: client | O6: ticker | P6: description | Q6: short_name_yf | R6: long_name_yf | S6: summary_yf | T6: note
A7: Theme | B7: USD | C7: ELECTION | D7: composite | E7: lognormal | F7: {=_xlfn.SWITCH(data[[#This Row],[diffusion_type]],"lognormal",0.0001,"normal",-0.01)*IF(data[[#This Row],[asset_class]]="Vol",1,1)} -> 0.0001 | J7: {=_xlfn.XLOOKUP(data[[#This Row],[factor_name]],_xlfn.ANCHORARRAY(composites!$I$2),_xlfn.ANCHORARRAY(composites!$J$2))} -> #N/A | K7: 1 | L7: 0 | M7: 0 | N7: 0 | O7: =data[[#This Row],[factor_name]] -> DIA | P7: {=_xlfn.IFS(data[[#This Row],[description_override]]<>"",data[[#This Row],[description_override]],data[[#This Row],[Description_GPT]]<>"",data[[#This Row],[Description_GPT]],data[[#This Row],[Underlying]]<>"",data[[#This Row],[Underlying]],TRUE,"-")} -> Dow Jones 30 | Q7: =_xlfn.XLOOKUP(data[[#This Row],[ticker]],yf_desc[ticker],yf_desc[shortName],"-") -> SPDR Dow Jones Industrial Avera | R7: =_xlfn.XLOOKUP(data[[#This Row],[ticker]],yf_desc[ticker],yf_desc[longName],"-") -> SPDR Dow Jones Industrial Average ETF Trust | S7: =_xlfn.XLOOKUP(data[[#This Row],[ticker]],yf_desc[ticker],yf_desc[longBusinessSummary],"-") -> The Trust’s Portfolio consists of substantially all of the component common stocks that comprise the DJIA, which are weighted in accordance with the terms of the Trust Agreement.
A12: ELECTION | B12: XLF | C12: 1.5
A13: ELECTION | B13: ICLN | C13: -1
A14: ELECTION | B14: IWM | C14: 1.5
A15: ELECTION | B15: FEZ | C15: -1

Sheet composites
A1: portfolio_name | B1: factor_name | C1: weight | N1: vol | O1: volweight
A2: FED | B2: SHY | C2: 1 | E2: {=_xlfn.XLOOKUP(composities[portfolio_name],data[factor_name],data[Active])} -> 1 | H2: {=TEXT(composities[weight],IF(INT(composities[weight]*100)/100=composities[weight],"General","0.00"))} -> 1 | I2: {=_xlfn.UNIQUE(composities[portfolio_name])} -> FED | J2: {=_xlfn.BYROW(_xlfn.ANCHORARRAY(I2),_xlfn.LAMBDA(_xlpm.portfolio,_xlfn.TEXTJOIN(", ",,_xlfn.BYROW(_xlfn._xlws.FILTER(_xlfn.HSTACK(composities[factor_name],_xlfn.ANCHORARRAY($H$2)),composities[portfolio_name]=_xlpm.portfolio),_xlfn.LAMBDA(_xlpm.factor,_xlfn.TEXTJOIN(" ",,_xlpm.factor))))))} -> SHY 1, BSV 1 | X2: {=composities[portfolio_name]<>OFFSET(composities[portfolio_name],-1,0)} -> TRUE | AE2: TRUMP | AF2: unit | AI2: AI | AJ2: FED
A3: FED | B3: BSV | C3: 1 | E3: 1 | H3: 1 | I3: AI | J3: AIQ 1, QQQ 0.25, IWM -0.25 | X3: FALSE | AD3: XLF | AE3: 1 | AF3: capital
A4: AI | B4: AIQ | C4: 1 | E4: 1 | H4: 1 | I4: GEOPOLITICS | J4: GLD 0.65, USO 0.3, ^VIX3M -0.15, FEZ -0.05 | X4: TRUE | AD4: ICLN | AE4: -1 | AF4: capital | AG4: or TEN
A5: AI | B5: QQQ | C5: 0.25 | E5: 1 | H5: 0.25 | I5: 2s10s | J5: SHY -3.86, IEF 1 | X5: FALSE | AD5: IWM | AE5: 1 | AF5: capital
A6: AI | B6: IWM | C6: -0.25 | E6: 1 | H6: -0.25 | I6: XLPXLY | J6: XLP 1, XLY -1 | X6: FALSE | AD6: SX5E | AE6: -1 | AF6: capital
A7: GEOPOLITICS | B7: GLD | C7: 0.65 | E7: 1 | H7: 0.65 | I7: TRADEWAR | J7: GLD 0.21, FXY 0.30, FXF 0.37, ^VIX3M -0.04, XLP 0.15, XLY -0.15 | X7: TRUE | AD7: USD02 | AE7: 1 | AF7: vol | AG7: govt spending
A8: GEOPOLITICS | B8: USO | C8: 0.3 | E8: 1 | H8: 0.3 | I8: IRAN | J8: USO 1 | X8: FALSE | AA8: AIQ | AB8: 1 | AD8: USD10 | AE8: -1 | AF8: vol
A9: GEOPOLITICS | B9: ^VIX3M | C9: -0.15 | E9: 1 | H9: -0.15 | I9: SEMI-SOFT | J9: SMH 1, IGV -1, QQQ 1 | X9: FALSE | AA9: QQQ | AB9: 1 | AD9: TIP | AE9: 1
A10: GEOPOLITICS | B10: FEZ | C10: -0.05 | E10: 1 | F10: x | H10: -0.05 | I10: PRIVATES | J10: PSP 0.5, XLF -0.5, BKLN 0.5, LQDH -0.5 | X10: FALSE | AA10: IWM | AB10: -1 | AD10: TLT | AE10: -1 | AG10: or TLT v. VTIP
A11: 2s10s | B11: SHY | C11: =-C12*Y15/Y13 -> -3.863388 | E11: 1 | H11: -3.86 | X11: TRUE | AD11: AIQ | AI11: 1
A12: 2s10s | B12: IEF | C12: 1 | E12: 1 | H12: 1 | X12: FALSE | AD12: RSP | AI12: -1
A13: XLPXLY | B13: XLP | C13: 1 | E13: 1 | H13: 1 | X13: TRUE | Y13: 1.83 | AD13: SOFRZ5
A14: XLPXLY | B14: XLY | C14: -1 | E14: 1 | H14: -1 | X14: FALSE
A15: TRADEWAR | B15: GLD | C15: {=O18/N18*$P$18/SUM(ABS(($O$18:$O$22)))} -> 0.20547945 | E15: 1 | H15: 0.21 | X15: TRUE | Y15: 7.07 | Z15: =Y15/Y13 -> 3.863388 | AD15: SOFRZ4
A16: TRADEWAR | B16: FXY | C16: =O19/N19*$P$18/COUNT($O$18:$O$22) -> 0.2970297 | E16: 1 | H16: 0.30 | O16: 3 | Q16: XLPXLY | R16: 22 | X16: FALSE
A17: TRADEWAR | B17: FXF | C17: =O20/N20*$P$18/COUNT($O$18:$O$22) -> 0.36585366 | E17: 1 | H17: 0.37 | R17: 16 | X17: FALSE
A18: TRADEWAR | B18: ^VIX3M | C18: =O21/N21*$P$18/COUNT($O$18:$O$22) -> -0.0375 | E18: 1 | H18: -0.04 | N18: 14.6 | O18: 1 | P18: 15 | W18: {=C15:C18*N18:N21} -> 3 | X18: FALSE
A19: TRADEWAR | B19: =B13 -> XLP | C19: =O22/N22*$P$18/COUNT($O$18:$O$22) -> 0.15 | E19: 1 | H19: 0.15 | N19: 10.1 | O19: 1 | W19: 3 | X19: FALSE
A20: TRADEWAR | B20: =B14 -> XLY | C20: =-C19 -> -0.15 | E20: 1 | H20: -0.15 | N20: 8.2 | O20: 1 | W20: 3 | X20: FALSE | Z20: Can also short discretionary/staples
A21: IRAN | B21: USO | C21: 1 | E21: 1 | H21: 1 | N21: 80 | O21: -1 | W21: -3 | X21: TRUE
A22: SEMI-SOFT | B22: SMH | C22: 1 | E22: 1 | H22: 1 | N22: 20 | O22: 1 | X22: TRUE
A23: SEMI-SOFT | B23: IGV | C23: -1 | E23: 1 | H23: -1 | X23: FALSE
A24: SEMI-SOFT | B24: QQQ | C24: 1 | E24: 1 | H24: 1 | X24: FALSE
A25: PRIVATES | B25: PSP | C25: 0.5 | E25: 1 | H25: 0.5 | X25: TRUE
A26: PRIVATES | B26: XLF | C26: -0.5 | E26: 1 | H26: -0.5 | X26: FALSE
A27: PRIVATES | B27: BKLN | C27: 0.5 | E27: 1 | H27: 0.5 | X27: FALSE
A28: PRIVATES | B28: LQDH | C28: -0.5 | E28: 1 | H28: -0.5 | X28: FALSE
Q34: =_xlfn.TEXTJOIN(", ",,_xlfn.ANCHORARRAY(Q36)) -> #VALUE!
N36: 14.6 | O36: 3 | Q36: {=_xlfn._xlws.FILTER(composities[[factor_name]:[weight]],composities[portfolio_name]="ELECTION")} -> #VALUE! | T36: {=_xlfn._xlws.FILTER(composities[[factor_name]:[weight]],composities[portfolio_name]="2s10s")} -> SHY | U36: -3.863388 | V36: {=_xlfn.LET(_xlpm.f,_xlfn._xlws.FILTER(composities[[factor_name]:[weight]],composities[portfolio_name]="ELECTION"),_xlfn.TEXTJOIN("; ",,_xlfn.BYROW(_xlpm.f,_xlfn.LAMBDA(_xlpm.row,_xlfn.TEXTJOIN(" ",,_xlpm.row)))))} -> #VALUE! | W36: {=C38:C41*N36:N39} -> 3
N37: 10.1 | O37: 3 | T37: IEF | U37: 1 | W37: 3
A38: TRADEWAR_OLD | B38: GLD | C38: =O36/N36 -> 0.20547945 | N38: 8.2 | O38: 3 | W38: 3 | Z38: Can also short discretionary/staples
A39: TRADEWAR_OLD | B39: FXY | C39: =O37/N37 -> 0.2970297 | N39: 80 | O39: =-SUM(O36:O38) -> -9 | W39: -9
A40: TRADEWAR_OLD | B40: FXF | C40: =O38/N38 -> 0.36585366
A41: TRADEWAR_OLD | B41: ^VIX3M | C41: =O39/N39 -> -0.1125

Sheet data
A1: asset_class | B1: region | C1: factor_name | D1: source | E1: diffusion_type | F1: multiplier | G1: factor_name_new | H1: description_override | I1: Description_GPT | J1: Underlying | K1: Active | L1: hyper_factor | M1: composite | N1: client | O1: ticker | P1: description | Q1: short_name_yf | R1: long_name_yf | S1: summary_yf | T1: note
A2: Equities | B2: USD | C2: SPY | D2: yfinance | E2: lognormal | F2: {=_xlfn.SWITCH(data[[#This Row],[diffusion_type]],"lognormal",0.0001,"normal",-0.01)*IF(data[[#This Row],[asset_class]]="Vol",1,1)} -> 0.0001 | G2: SPX | H2: S&P 500 | I2: SPDR S&P 500 ETF Trust | J2: S&P 500 Index | K2: 1 | L2: 1 | M2: 0 | N2: 0 | O2: =data[[#This Row],[factor_name]] -> SPY | P2: {=_xlfn.IFS(data[[#This Row],[description_override]]<>"",data[[#This Row],[description_override]],data[[#This Row],[Description_GPT]]<>"",data[[#This Row],[Description_GPT]],data[[#This Row],[Underlying]]<>"",data[[#This Row],[Underlying]],TRUE,"-")} -> S&P 500 | Q2: =_xlfn.XLOOKUP(data[[#This Row],[ticker]],yf_desc[ticker],yf_desc[shortName],"-") -> SPDR S&P 500 | R2: =_xlfn.XLOOKUP(data[[#This Row],[ticker]],yf_desc[ticker],yf_desc[longName],"-") -> SPDR S&P 500 ETF | S2: =_xlfn.XLOOKUP(data[[#This Row],[ticker]],yf_desc[ticker],yf_desc[longBusinessSummary],"-") -> The trust seeks to achieve its investment objective by holding a portfolio of the common stocks that are included in the index, with the weight of each stock in the portfolio substantially corresponding to the weight of such stock in the index.
A3: Equities | B3: USD | C3: IWM | D3: yfinance | E3: lognormal | F3: {=_xlfn.SWITCH(data[[#This Row],[diffusion_type]],"lognormal",0.0001,"normal",-0.01)*IF(data[[#This Row],[asset_class]]="Vol",1,1)} -> 0.0001 | G3: RTY | H3: Russell 2000 | I3: iShares Russell 2000 ETF | J3: Russell 2000 Index | K3: 1 | L3: 0 | M3: 0 | N3: 0 | O3: =data[[#This Row],[factor_name]] -> IWM | P3: {=_xlfn.IFS(data[[#This Row],[description_override]]<>"",data[[#This Row],[description_override]],data[[#This Row],[Description_GPT]]<>"",data[[#This Row],[Description_GPT]],data[[#This Row],[Underlying]]<>"",data[[#This Row],[Underlying]],TRUE,"-")} -> Russell 2000 | Q3: =_xlfn.XLOOKUP(data[[#This Row],[ticker]],yf_desc[ticker],yf_desc[shortName],"-") -> iShares Russell 2000 ETF | R3: =_xlfn.XLOOKUP(data[[#This Row],[ticker]],yf_desc[ticker],yf_desc[longName],"-") -> iShares Russell 2000 ETF | S3: =_xlfn.XLOOKUP(data[[#This Row],[ticker]],yf_desc[ticker],yf_desc[longBusinessSummary],"-") -> The fund generally invests at least 80% of its assets in the component securities of its underlying index and in investments that have economic characteristics that are substantially identical to the component securities of its underlying index (i.e., depositary receipts representing securities of the underlying index) and may invest up to 20% of its assets in certain futures, options and swap contracts, cash and cash equivalents. | Y3: L1 = L0 + chg(F)*M = L0 + R*M
A4: Equities | B4: USD | C4: MDY | D4: yfinance | E4: lognormal | F4: {=_xlfn.SWITCH(data[[#This Row],[diffusion_type]],"lognormal",0.0001,"normal",-0.01)*IF(data[[#This Row],[asset_class]]="Vol",1,1)} -> 0.0001 | G4: MCAP | H4: S&P 400 | I4: SPDR S&P MidCap 400 ETF Trust | J4: S&P MidCap 400 Index | K4: 1 | L4: 0 | M4: 0 | N4: 0 | O4: =data[[#This Row],[factor_name]] -> MDY | P4: {=_xlfn.IFS(data[[#This Row],[description_override]]<>"",data[[#This Row],[description_override]],data[[#This Row],[Description_GPT]]<>"",data[[#This Row],[Description_GPT]],data[[#This Row],[Underlying]]<>"",data[[#This Row],[Underlying]],TRUE,"-")} -> S&P 400 | Q4: =_xlfn.XLOOKUP(data[[#This Row],[ticker]],yf_desc[ticker],yf_desc[shortName],"-") -> SPDR S&P MidCap 400 ETF Trust | R4: =_xlfn.XLOOKUP(data[[#This Row],[ticker]],yf_desc[ticker],yf_desc[longName],"-") -> SPDR S&P MIDCAP 400 ETF Trust | S4: =_xlfn.XLOOKUP(data[[#This Row],[ticker]],yf_desc[ticker],yf_desc[longBusinessSummary],"-") -> The Trust seeks to achieve its investment objective by holding a portfolio of the common stocks that are included in the index (the “Portfolio”), with the weight of each stock in the Portfolio substantially corresponding to the weight of such stock in the index.
A5: Equities | B5: USD | C5: RSP | D5: yfinance | E5: lognormal | F5: {=_xlfn.SWITCH(data[[#This Row],[diffusion_type]],"lognormal",0.0001,"normal",-0.01)*IF(data[[#This Row],[asset_class]]="Vol",1,1)} -> 0.0001 | H5: S&P 500 EW | K5: 1 | L5: 0 | M5: 0 | N5: 0 | O5: =data[[#This Row],[factor_name]] -> RSP | P5: {=_xlfn.IFS(data[[#This Row],[description_override]]<>"",data[[#This Row],[description_override]],data[[#This Row],[Description_GPT]]<>"",data[[#This Row],[Description_GPT]],data[[#This Row],[Underlying]]<>"",data[[#This Row],[Underlying]],TRUE,"-")} -> S&P 500 EW | Q5: =_xlfn.XLOOKUP(data[[#This Row],[ticker]],yf_desc[ticker],yf_desc[shortName],"-") -> Invesco S&P 500 Equal Weight ET | R5: =_xlfn.XLOOKUP(data[[#This Row],[ticker]],yf_desc[ticker],yf_desc[longName],"-") -> Invesco S&P 500 Equal Weight ETF | S5: =_xlfn.XLOOKUP(data[[#This Row],[ticker]],yf_desc[ticker],yf_desc[longBusinessSummary],"-") -> The fund generally will invest at least 90% of its total assets in securities that comprise the underlying index. Strictly in accordance with its guidelines and mandated procedures, the index provider compiles, maintains and calculates the underlying index, which consists of all of the of the S&P 500® Index. | Y5: return = chg(factor) * multiplier
A6: Equities | B6: USD | C6: QQQ | D6: yfinance | E6: lognormal | F6: {=_xlfn.SWITCH(data[[#This Row],[diffusion_type]],"lognormal",0.0001,"normal",-0.01)*IF(data[[#This Row],[asset_class]]="Vol",1,1)} -> 0.0001 | G6: NDX | H6: Nasdaq 100 | I6: Invesco QQQ Trust | J6: Nasdaq-100 Index | K6: 1 | L6: 0 | M6: 0 | N6: 0 | O6: =data[[#This Row],[factor_name]] -> QQQ | P6: {=_xlfn.IFS(data[[#This Row],[description_override]]<>"",data[[#This Row],[description_override]],data[[#This Row],[Description_GPT]]<>"",data[[#This Row],[Description_GPT]],data[[#This Row],[Underlying]]<>"",data[[#This Row],[Underlying]],TRUE,"-")} -> Nasdaq 100 | Q6: =_xlfn.XLOOKUP(data[[#This Row],[ticker]],yf_desc[ticker],yf_desc[shortName],"-") -> Invesco QQQ Trust, Series 1 | R6: =_xlfn.XLOOKUP(data[[#This Row],[ticker]],yf_desc[ticker],yf_desc[longName],"-") -> Invesco QQQ Trust | S6: =_xlfn.XLOOKUP(data[[#This Row],[ticker]],yf_desc[ticker],yf_desc[longBusinessSummary],"-") -> To maintain the correspondence between the composition and weights of the securities in the trust (the "securities") and the stocks in the NASDAQ-100 Index®, the adviser adjusts the securities from time to time to conform to periodic changes in the identity and/or relative weights of index securities. The composition and weighting of the securities portion of a portfolio deposit are also adjusted to conform to changes in the index.
A7: Equities | B7: USD | C7: DIA | D7: yfinance | E7: lognormal | F7: {=_xlfn.SWITCH(data[[#This Row],[diffusion_type]],"lognormal",0.0001,"normal",-0.01)*IF(data[[#This Row],[asset_class]]="Vol",1,1)} -> 0.0001 | G7: DOW | H7: Dow Jones 30 | I7: SPDR Dow Jones Industrial Average ETF Trust | J7: Dow Jones Industrial Average | K7: 1 | L7: 0 | M7: 0 | N7: 0 | O7: =data[[#This Row],[factor_name]] -> DIA | P7: {=_xlfn.IFS(data[[#This Row],[description_override]]<>"",data[[#This Row],[description_override]],data[[#This Row],[Description_GPT]]<>"",data[[#This Row],[Description_GPT]],data[[#This Row],[Underlying]]<>"",data[[#This Row],[Underlying]],TRUE,"-")} -> Dow Jones 30 | Q7: =_xlfn.XLOOKUP(data[[#This Row],[ticker]],yf_desc[ticker],yf_desc[shortName],"-") -> SPDR Dow Jones Industrial Avera | R7: =_xlfn.XLOOKUP(data[[#This Row],[ticker]],yf_desc[ticker],yf_desc[longName],"-") -> SPDR Dow Jones Industrial Average ETF Trust | S7: =_xlfn.XLOOKUP(data[[#This Row],[ticker]],yf_desc[ticker],yf_desc[longBusinessSummary],"-") -> The Trust’s Portfolio consists of substantially all of the component common stocks that comprise the DJIA, which are weighted in accordance with the terms of the Trust Agreement.
A8: Sector | B8: USD | C8: XLK | D8: yfinance | E8: lognormal | F8: {=_xlfn.SWITCH(data[[#This Row],[diffusion_type]],"lognormal",0.0001,"normal",-0.01)*IF(data[[#This Row],[asset_class]]="Vol",1,1)} -> 0.0001 | H8: Technology | I8: Technology Select Sector SPDR Fund | K8: 1 | L8: 0 | M8: 0 | N8: 0 | O8: =data[[#This Row],[factor_name]] -> XLK | P8: {=_xlfn.IFS(data[[#This Row],[description_override]]<>"",data[[#This Row],[description_override]],data[[#This Row],[Description_GPT]]<>"",data[[#This Row],[Description_GPT]],data[[#This Row],[Underlying]]<>"",data[[#This Row],[Underlying]],TRUE,"-")} -> Technology | Q8: =_xlfn.XLOOKUP(data[[#This Row],[ticker]],yf_desc[ticker],yf_desc[shortName],"-") -> SPDR Select Sector Fund - Techn | R8: =_xlfn.XLOOKUP(data[[#This Row],[ticker]],yf_desc[ticker],yf_desc[longName],"-") -> The Technology Select Sector SPDR Fund | S8: =_xlfn.XLOOKUP(data[[#This Row],[ticker]],yf_desc[ticker],yf_desc[longBusinessSummary],"-") -> In seeking to track the performance of the index, the fund employs a replication strategy, which means that the fund typically invests in substantially all of the securities represented in the index in approximately the same proportions as the index. It generally invests substantially all, but at least 95%, of its total assets in the securities comprising the index. The fund is non-diversified.
A9: Sector | B9: USD | C9: XLI | D9: yfinance | E9: lognormal | F9: {=_xlfn.SWITCH(data[[#This Row],[diffusion_type]],"lognormal",0.0001,"normal",-0.01)*IF(data[[#This Row],[asset_class]]="Vol",1,1)} -> 0.0001 | H9: Industrials | I9: Industrial Select Sector SPDR Fund | K9: 1 | L9: 0 | M9: 0 | N9: 0 | O9: =data[[#This Row],[factor_name]] -> XLI | P9: {=_xlfn.IFS(data[[#This Row],[description_override]]<>"",data[[#This Row],[description_override]],data[[#This Row],[Description_GPT]]<>"",data[[#This Row],[Description_GPT]],data[[#This Row],[Underlying]]<>"",data[[#This Row],[Underlying]],TRUE,"-")} -> Industrials | Q9: =_xlfn.XLOOKUP(data[[#This Row],[ticker]],yf_desc[ticker],yf_desc[shortName],"-") -> SPDR Select Sector Fund - Indus | R9: =_xlfn.XLOOKUP(data[[#This Row],[ticker]],yf_desc[ticker],yf_desc[longName],"-") -> The Industrial Select Sector SPDR Fund | S9: =_xlfn.XLOOKUP(data[[#This Row],[ticker]],yf_desc[ticker],yf_desc[longBusinessSummary],"-") -> Under normal market conditions, the fund generally invests substantially all, but at least 95%, of its total assets in the securities comprising the index. The index includes companies that have been identified as Industrial companies by the Global Industry Classification Standard, including securities of companies from the following industries: aerospace and defense; industrial conglomerates; marine transportation. It is non-diversified.
A10: Sector | B10: USD | C10: XLF | D10: yfinance | E10: lognormal | F10: {=_xlfn.SWITCH(data[[#This Row],[diffusion_type]],"lognormal",0.0001,"normal",-0.01)*IF(data[[#This Row],[asset_class]]="Vol",1,1)} -> 0.0001 | H10: Financials | I10: Financial Select Sector SPDR Fund | K10: 1 | L10: 0 | M10: 0 | N10: 0 | O10: =data[[#This Row],[factor_name]] -> XLF | P10: {=_xlfn.IFS(data[[#This Row],[description_override]]<>"",data[[#This Row],[description_override]],data[[#This Row],[Description_GPT]]<>"",data[[#This Row],[Description_GPT]],data[[#This Row],[Underlying]]<>"",data[[#This Row],[Underlying]],TRUE,"-")} -> Financials | Q10: =_xlfn.XLOOKUP(data[[#This Row],[ticker]],yf_desc[ticker],yf_desc[shortName],"-") -> SPDR Select Sector Fund - Finan | R10: =_xlfn.XLOOKUP(data[[#This Row],[ticker]],yf_desc[ticker],yf_desc[longName],"-") -> The Financial Select Sector SPDR Fund | S10: =_xlfn.XLOOKUP(data[[#This Row],[ticker]],yf_desc[ticker],yf_desc[longBusinessSummary],"-") -> The fund generally invests substantially all, but at least 95%, of its total assets in the securities comprising the index. The index includes companies that have been identified as Financial companies by the Global Industry Classification Standard, including securities of companies from the following industries: financial services; insurance; banks; capital markets; mortgage real estate investment trusts; and consumer finance. The fund is non-diversified.
A11: Sector | B11: USD | C11: KRE | D11: yfinance | E11: lognormal | F11: {=_xlfn.SWITCH(data[[#This Row],[diffusion_type]],"lognormal",0.0001,"normal",-0.01)*IF(data[[#This Row],[asset_class]]="Vol",1,1)} -> 0.0001 | H11: Regional Banks | I11: SPDR S&P Regional Banking ETF | K11: 1 | L11: 0 | M11: 0 | N11: 0 | O11: =data[[#This Row],[factor_name]] -> KRE | P11: {=_xlfn.IFS(data[[#This Row],[description_override]]<>"",data[[#This Row],[description_override]],data[[#This Row],[Description_GPT]]<>"",data[[#This Row],[Description_GPT]],data[[#This Row],[Underlying]]<>"",data[[#This Row],[Underlying]],TRUE,"-")} -> Regional Banks | Q11: =_xlfn.XLOOKUP(data[[#This Row],[ticker]],yf_desc[ticker],yf_desc[shortName],"-") -> SPDR S&P Regional Banking ETF | R11: =_xlfn.XLOOKUP(data[[#This Row],[ticker]],yf_desc[ticker],yf_desc[longName],"-") -> SPDR S&P Regional Banking ETF | S11: =_xlfn.XLOOKUP(data[[#This Row],[ticker]],yf_desc[ticker],yf_desc[longBusinessSummary],"-") -> In seeking to track the performance of the S&P Regional Banks Select Industry Index (the "index"), the fund employs a sampling strategy. It generally invests substantially all, but at least 80%, of its total assets in the securities comprising the index. The index represents the regional banks segment of the S&P Total Market Index ("S&P TMI").
A12: Sector | B12: USD | C12: XLC | D12: yfinance | E12: lognormal | F12: {=_xlfn.SWITCH(data[[#This Row],[diffusion_type]],"lognormal",0.0001,"normal",-0.01)*IF(data[[#This Row],[asset_class]]="Vol",1,1)} -> 0.0001 | H12: Communications | I12: Communication Services Select Sector SPDR | K12: 1 | L12: 0 | M12: 0 | N12: 0 | O12: =data[[#This Row],[factor_name]] -> XLC | P12: {=_xlfn.IFS(data[[#This Row],[description_override]]<>"",data[[#This Row],[description_override]],data[[#This Row],[Description_GPT]]<>"",data[[#This Row],[Description_GPT]],data[[#This Row],[Underlying]]<>"",data[[#This Row],[Underlying]],TRUE,"-")} -> Communications | Q12: =_xlfn.XLOOKUP(data[[#This Row],[ticker]],yf_desc[ticker],yf_desc[shortName],"-") -> The Communication Services Sele | R12: =_xlfn.XLOOKUP(data[[#This Row],[ticker]],yf_desc[ticker],yf_desc[longName],"-") -> The Communication Services Select Sector SPDR ETF Fund | S12: =_xlfn.XLOOKUP(data[[#This Row],[ticker]],yf_desc[ticker],yf_desc[longBusinessSummary],"-") -> Normally, the fund generally invests substantially all, but at least 95%, of its total assets in the securities comprising the index. The index includes companies that have been identified as Communication Services companies by the GICS®, including securities of companies from the following industries: diversified telecommunication services; wireless telecommunication services; media; entertainment; and interactive media & services. The fund is non-diversified.
A13: Sector | B13: USD | C13: XLE | D13: yfinance | E13: lognormal | F13: {=_xlfn.SWITCH(data[[#This Row],[diffusion_type]],"lognormal",0.0001,"normal",-0.01)*IF(data[[#This Row],[asset_class]]="Vol",1,1)} -> 0.0001 | H13: Energy | I13: Energy Select Sector SPDR Fund | K13: 1 | L13: 0 | M13: 0 | N13: 0 | O13: =data[[#This Row],[factor_name]] -> XLE | P13: {=_xlfn.IFS(data[[#This Row],[description_override]]<>"",data[[#This Row],[description_override]],data[[#This Row],[Description_GPT]]<>"",data[[#This Row],[Description_GPT]],data[[#This Row],[Underlying]]<>"",data[[#This Row],[Underlying]],TRUE,"-")} -> Energy | Q13: =_xlfn.XLOOKUP(data[[#This Row],[ticker]],yf_desc[ticker],yf_desc[shortName],"-") -> SPDR Select Sector Fund - Energ | R13: =_xlfn.XLOOKUP(data[[#This Row],[ticker]],yf_desc[ticker],yf_desc[longName],"-") -> The Energy Select Sector SPDR Fund | S13: =_xlfn.XLOOKUP(data[[#This Row],[ticker]],yf_desc[ticker],yf_desc[longBusinessSummary],"-") -> In seeking to track the performance of the index, the fund employs a replication strategy. It generally invests substantially all, but at least 95%, of its total assets in the securities comprising the index. The index includes companies that have been identified as Energy companies by the GICS®, including securities of companies from the following industries: oil, gas and consumable fuels; and energy equipment and services. It is non-diversified.
A14: Sector | B14: USD | C14: XLY | D14: yfinance | E14: lognormal | F14: {=_xlfn.SWITCH(data[[#This Row],[diffusion_type]],"lognormal",0.0001,"normal",-0.01)*IF(data[[#This Row],[asset_class]]="Vol",1,1)} -> 0.0001 | H14: Discretionary | I14: Consumer Discretionary Select Sector SPDR | K14: 1 | L14: 0 | M14: 0 | N14: 0 | O14: =data[[#This Row],[factor_name]] -> XLY | P14: {=_xlfn.IFS(data[[#This Row],[description_override]]<>"",data[[#This Row],[description_override]],data[[#This Row],[Description_GPT]]<>"",data[[#This Row],[Description_GPT]],data[[#This Row],[Underlying]]<>"",data[[#This Row],[Underlying]],TRUE,"-")} -> Discretionary | Q14: =_xlfn.XLOOKUP(data[[#This Row],[ticker]],yf_desc[ticker],yf_desc[shortName],"-") -> SPDR Select Sector Fund - Consu | R14: =_xlfn.XLOOKUP(data[[#This Row],[ticker]],yf_desc[ticker],yf_desc[longName],"-") -> The Consumer Discretionary Select Sector SPDR Fund | S14: =_xlfn.XLOOKUP(data[[#This Row],[ticker]],yf_desc[ticker],yf_desc[longBusinessSummary],"-") -> The Advisor employs a replication strategy. The fund generally invests substantially all, but at least 95%, of its total assets in the securities comprising the index. The index includes companies that have been identified as Consumer Discretionary companies by the Global Industry Classification Standard (GICS®). It is non-diversified.
